<mujoco model="handover_sim_v7">
  <compiler angle="radian"/>
  <option gravity="0 0 0" timestep="0.002"/>

  <asset>
    <mesh name="object_mesh" file="object/rubber_duck.stl" scale="0.001 0.001 0.001"/>
  </asset>

  <worldbody>

    <!-- 바닥 -->
    <geom name="floor" type="plane" pos="0 0 0" size="1 1 0.1" rgba="0.9 0.9 0.9 1"/>

    <!-- 오브젝트 -->
    <body name="object" pos="0 0 0.42">
      <geom type="mesh" mesh="object_mesh" rgba="0.5 0.3 0.2 1" mass="0.1"/>
    </body>

    <!-- 로봇 암 -->
    <body name="robot_base" pos="0 -0.5 0.4">

      <!-- Shoulder -->
      <joint name="joint1" type="hinge" axis="0 0 1" range="-1.57 1.57"/>
      <geom type="sphere" size="0.05" rgba="0.5 0.5 0.5 1" mass="1.0"/>

      <body name="link1" pos="0 0 0.0">
        <geom type="capsule" pos="0 0 0.12" size="0.02 0.12" rgba="0 0 1 1" mass="0.2"/>

        <!-- Elbow -->
        <joint name="joint2" type="hinge" axis="0 1 0" range="-1.57 1.57"/>

        <body name="link2" pos="0 0 0.24">
          <geom type="capsule" pos="0 0 0.12" size="0.02 0.12" rgba="0 0 1 1" mass="0.2"/>

          <!-- Wrist -->
          <joint name="joint3" type="hinge" axis="0 1 0" range="-1.57 1.57"/>

          <body name="link3" pos="0 0 0.24">
            <geom type="capsule" pos="0 0 0.1" size="0.02 0.1" rgba="0 0 1 1" mass="0.2"/>

            <!-- Gripper palm -->
            <body name="gripper" pos="0 0 0.2">
              <geom type="cylinder" size="0.01 0.01" rgba="0 1 0 1" mass="0.1"/>

              <!-- Left finger -->
              <body name="finger_left" pos="-0.015 0 0">
                <joint name="finger_left_joint" type="slide" axis="1 0 0" range="0 0.01"/>
                <geom type="box" size="0.005 0.005 0.02" rgba="1 0 0 1" mass="0.05"/>
              </body>

              <!-- Right finger -->
              <body name="finger_right" pos="0.015 0 0">
                <joint name="finger_right_joint" type="slide" axis="1 0 0" range="-0.01 0"/>
                <geom type="box" size="0.005 0.005 0.02" rgba="1 0 0 1" mass="0.05"/>
              </body>

              <!-- Gripper-mounted camera -->
              <camera name="gripper_cam" pos="0 0 0.05" euler="0 0 0"/>
            </body>
          </body>
        </body>
      </body>
    </body>

    <!-- Receiver viewpoint camera -->
    <camera name="receiver_cam" pos="0.5 0 0.8" euler="0 0 -1.57"/>
  </worldbody>

  <!-- Actuator: 4 DOF (arm 3개 + gripper 1개) -->
  <actuator>
    <position name="act_joint1" joint="joint1" kp="100"/>
    <position name="act_joint2" joint="joint2" kp="100"/>
    <position name="act_joint3" joint="joint3" kp="100"/>

    <!-- Gripper actuator: 좌우 finger를 동시에 제어 -->
    <general name="act_gripper" joint="finger_left_joint" gainprm="1"/>
    <general name="act_gripper_mirror" joint="finger_right_joint" gainprm="-1"/>
  </actuator>

</mujoco>
